Workbook
Name _aff306: '[1]BALANCE BFI INTERNAIONAL AU 30 '!$G$1:$G$65536
Name _DTF1: [2]Paramètres!$B$6
Name _sol306: '[1]BALANCE BFI INTERNAIONAL AU 30 '!$F$1:$F$65536
Name acc: [3]N_ACCTUN!$A$12:$C$629
Name ACLARACIONES_AYUDA: #REF!
Name AFEC: '[4]BALANCE AU 30.06.01'!$F$1:$F$65536
Name AFF: '[4]BALANCE AU 30.06.01'!$F$1:$F$65536
Name Affect: '[5]Balance comparative (2)'!$J$1:$J$65536
Name affect1: #REF!
Name affectation: [6]Bilan!$D$3:$D$239
Name AFFRT: [7]sum_ert!$A$1:$A$65536
Name am: [8]!am
Name AYUDA_PLAZO_ENTREGA: #REF!
Name az: [8]!az
Name Bal_CodeGroupeAnalyse: #REF!
Name Bal_CompteDebut: #REF!
Name Bal_CompteFin: #REF!
Name Bal_DateDebut: #REF!
Name Bal_DateFin: #REF!
Name Bal_NomGroupeAnalyse: #REF!
Name Bal_TypeEcriture: #REF!
Name BALANCE000999: #REF!
Name Balx_CodeGroupeAnalyse: [9]BALANCEAUX!$B$2
Name Balx_Compte: [9]BALANCEAUX!$D$2
Name Balx_DateDebut: [9]BALANCEAUX!$A$5
Name Balx_DateFin: [9]BALANCEAUX!$B$5
Name Balx_LibelleCompte: [9]BALANCEAUX!$D$3
Name Balx_NbLignes: [9]BALANCEAUX!#REF!
Name Balx_NomGroupeAnalyse: [9]BALANCEAUX!$B$3
Name Balx_TypeEcriture: [9]BALANCEAUX!$A$3
Name Beginning_Balance: #N/A
Name Beginning_Balance: #N/A
Name Beginning_Balance: #N/A
Name Beginning_Balance: #N/A
Name Beginning_Balance: #N/A
Name BIL_1: [10]BILAN!$P$3:$P$28,[10]BILAN!$G$3:$G$60
Name BIL_2: [10]BILAN!$Q$3:$Q$28,[10]BILAN!$H$3:$H$60
Name bilan: [8]!bilan
Name C_CLAVE_AYUDA: #REF!
Name Caseàcocher10_QuandClic: [8]!Caseàcocher10_QuandClic
Name Caseàcocher42_QuandClic: [8]!Caseàcocher42_QuandClic
Name CATE: [11]codes!$J$11:$J$14
Name CATE_NR.: [11]codes!$J$6
Name CDGR: [2]Paramètres!$A$1
Name CFA: #REF!
Name Charges: [8]!Charges
Name Choix_Imprimantes: [8]!Choix_Imprimantes
Name CODE_SEG: [12]Base.!$C$1:$C$65536
Name COM_BEB_AYUDA: #REF!
Name commentaires: [8]!commentaires
Name COMPARATIVO_AYUDA: #REF!
Name Contactos_AYUDA: #REF!
Name CURR: [11]codes!$F$5:$F$88
Name d: [8]!d
Name DATE: [13]Tréso!$B$5
Name Date_Paie: #REF!
Name Date_Paiement: DATE(YEAR(Début_Prêt),MONTH(Début_Prêt)+[0]!Payment_Number,DAY(Début_Prêt))
Name DATOS_AYUDA: #REF!
Name DC_AVW: #REF!
Name Début_Prêt: #REF!

Sheet Données
A1: Capacité nominale du système de production
A2: Désignation | B2: Nombre de sachet de 100 g/min | C2: Nombre de minute/jours | D2: Production moyenne journalière | E2: Capacité nominale mensuelle
A3: Capacité de Production moyenne forme coussin | B3: 68 | C3: =60*6 -> 360 | D3: =+B3*C3 -> 24480 | E3: =+D3*26 -> 636480
A4: Capacité de Production moyenne forme carré | B4: 43 | C4: =60*6 -> 360 | D4: =+B4*C4 -> 15480 | E4: =+D4*26 -> 402480
E6: =SUM(E3:E5) -> 1038960
A8: Rubrique | B8: Délai
A9: Délai de règlement Créances Clients | B9: 30 jours
A10: Délai de règlement dettes fournisseurs | B10: 30 jours
A11: Délai de démarrage | B11: 90 jours
A12: Nombre de jours / année | B12: 310 jours
A15: 1 kg Cacahuète necessite 60g/arome
A16: Une tonne de MP Nécessite 300 Dinars d'arome
A17: Prix d'achat emballage = 8,9 TND HT /Kg | B17: 11 | C17: =(8900/1000)*4 -> 35.6
A18: un sachet consomme 4 ou 5 gramme d'emballage(à 8 dinars le kg d'emballage , l'emballage de 100 gramme coute 32 millimes)
A19: Chaque carton comporte 36 Pièces de 100g
A20: le carton coute 0,600 TND | B20: 0.6
A22: Politique de vente c'est le porte à porte et se concentre essentiellement sur les grandes villes à savoir Tunis; Sousse et Sfax,
A23: Les achats MP emballage sont éffectués sur le marché local
A24: Les produits qui seront réalisés sont les produits salés
A25: le taux de déchet max 1%
A26: Prix d'achat MP
A27: Désignation de la rubrique | B27: P unitaire/Kg
A28: Mais | B28: 2.8
A29: Cacahuète | B29: 5.1
A30: Pois chiche | B30: 3.8
A31: Amande | B31: 25
A32: Acajou | B32: 22
A33: Pistache | B33: 24
A34: Noisette | B34: 24
A35: Aromes | B35: =10*2.2183 -> 22.183
A38: Poids
A39: Poid Brut en g | B39: Poid Net en g
A40: 100 | B40: 95
A41: 50 | B41: 45
A42: 400 | B42: 380
A45: Désignation de la rubrique | B45: QT produites mensuelle en Kg | C45: QT - sachet de 100 g | D45: PX UNIT | E45: Sachet de 100 g | F45: Prix de Vte unitaire
A46: PF Mais | B46: 3000 | C46: =+B46*10 -> 30000 | D46: 1 | E46: PF Mais | F46: 1
A47: PF Cacahuète | B47: 3000 | C47: =+B47*10 -> 30000 | D47: 1.4 | E47: PF Cacahuète | F47: 1.4
A48: PF Pois chiche | B48: 3000 | C48: =+B48*10 -> 30000 | D48: 1.2 | E48: PF Pois chiche | F48: 1.2
A49: PF Autres (noisette , pistche , acajou , amande) | B49: 1400 | C49: =+B49*10 -> 14000 | D49: 3.5 | E49: PF Autres (noisette , pistche , acajou , amande) | F49: 5
...

Sheet Hypothèse
A2: Régime de TVA
A3: Mais : TVA 6% sur achat/P°/Vente (tableau B paragraphe I.11 du code de TVA)
A4: Autres fruits secs : 6% au niveau du transformation ; Tableau B paragraphe III .11
A5: Autres fruits secs sont soumis au taux de 18%
A7: Les importations des équipements sont soumis au taux de TVA de 6% Tableau B bis paragraphe I.3.a voir note commune N° 21/2014
A9: Le taux de ristourne est de 10% du chiffre d'affaire
A10: Production =320/310 jours vente | D10: =320/310 -> 1.0322581
A11: consommation= 101% prod
A12: Achat = (consommation-SI)*13/12
A13: stock MP = Achat/13

Sheet Schémas fin
A3: Source de financement | B3: Valeur | C3: %
A4: Fonds propres | B4: 180000 | C4: =+B4/$B$6 -> 0.3
A5: Crédit à Moyen Terme | B5: 420000 | C5: =+B5/$B$6 -> 0.7
A6: Total | B6: =SUM(B4:B5) -> 600000
B7: =+B6-Investissements!C32 -> -0.064428897

Sheet Investissements
A3: Investissements | B3: Valeur en DT | C3: Taux | F3: 2016 | G3: 2017 | H3: 2018 | I3: 2019 | J3: 2020 | K3: 2021 | L3: 2022 | M3: Total Amort | N3: VCN
A4: Logiciels de gestion | B4: =+C22 -> 5000 | C4: 0.3333 | F4: =+B4*C4 -> 1666.5 | G4: =+F4 -> 1666.5 | H4: =+G4+0.5 -> 1667 | I4: 0 | J4: 0 | K4: 0 | L4: 0 | M4: =+SUM(F4:L4) -> 5000 | N4: =+B4-M4 -> 0
A5: Agencement et aménagement construction | B5: =+C24 -> 26358.5 | C5: 0.1 | F5: =+B5*C5 -> 2635.85 | G5: =+F5 -> 2635.85 | H5: =+G5 -> 2635.85 | I5: =+H5 -> 2635.85 | J5: =+I5 -> 2635.85 | K5: =+J5 -> 2635.85 | L5: =+K5 -> 2635.85 | M5: =+SUM(F5:L5) -> 18450.95 | N5: =+B5-M5 -> 7907.55
A6: Matériels industriels | B6: =+C25 -> 253709.4 | C6: 0.1 | F6: =+B6*C6 -> 25370.94 | G6: =+F6 -> 25370.94 | H6: =+G6 -> 25370.94 | I6: =+H6 -> 25370.94 | J6: =+I6 -> 25370.94 | K6: =+J6 -> 25370.94 | L6: =+K6 -> 25370.94 | M6: =+SUM(F6:L6) -> 177596.58 | N6: =+B6-M6 -> 76112.82
A7: Matériel de transport | B7: =+C26 -> 97000 | C7: 0.2 | F7: =+B7*C7 -> 19400 | G7: =+F7 -> 19400 | H7: =+G7 -> 19400 | I7: =+H7 -> 19400 | J7: =+I7 -> 19400 | K7: 0 | L7: 0 | M7: =+SUM(F7:L7) -> 97000 | N7: =+B7-M7 -> 0
A8: Matériels et mobiliers de bureau | B8: =+C27 -> 12000 | C8: 0.1 | F8: =+B8*C8 -> 1200 | G8: =+F8 -> 1200 | H8: =+G8 -> 1200 | I8: =+H8 -> 1200 | J8: =+I8 -> 1200 | K8: =+J8 -> 1200 | L8: =+K8 -> 1200 | M8: =+SUM(F8:L8) -> 8400 | N8: =+B8-M8 -> 3600
A9: Autres matériels | B9: =+C28 -> 3500 | C9: 0.1 | F9: =+B9*C9 -> 350 | G9: =+F9 -> 350 | H9: =+G9 -> 350 | I9: =+H9 -> 350 | J9: =+I9 -> 350 | K9: =+J9 -> 350 | L9: =+K9 -> 350 | M9: =+SUM(F9:L9) -> 2450 | N9: =+B9-M9 -> 1050
A10: Frais préliminaires | B10: =+C30 -> 20500 | C10: 0.3333 | F10: =+B10*C10 -> 6832.65 | G10: =+F10 -> 6832.65 | H10: =+B10-(F10+G10) -> 6834.7 | I10: 0 | J10: 0 | K10: 0 | L10: 0 | M10: =+SUM(F10:L10) -> 20500 | N10: =+B10-M10 -> 0
B11: =SUM(B4:B10) -> 418067.9 | F11: =SUM(F5:F10) -> 55789.44 | G11: =SUM(G5:G10) -> 55789.44 | H11: =SUM(H5:H10) -> 55791.49 | I11: =SUM(I5:I10) -> 48956.79 | J11: =SUM(J5:J10) -> 48956.79 | K11: =SUM(K5:K10) -> 29556.79 | L11: =SUM(L5:L10) -> 29556.79 | M11: =SUM(M5:M10) -> 324397.53 | N11: =SUM(N5:N10) -> 88670.37
A13: Production anuelle | F13: =+#REF! -> #REF! | G13: =+#REF! -> #REF! | H13: =+#REF! -> #REF! | I13: =+#REF! -> #REF! | J13: =+#REF! -> #REF!
A15: Cout d'amort unit | F15: =+F6/F13 -> #REF! | G15: =+G6/G13 -> #REF! | H15: =+H6/H13 -> #REF! | I15: =+I6/I13 -> #REF! | J15: =+J6/J13 -> #REF!
A17: Droit de douane
A18: frais de transit
A19: frais de transport
A21: Investissements | C21: Valeur en DT | D21: %
A22: Logiciels de gestion | C22: 5000 | D22: =+C22/$C$32 -> 0.0083333324
A23: Sous-total Immobilisations Incorporelles | C23: =SUM(C22) -> 5000 | D23: =+C23/$C$32 -> 0.0083333324
A24: Agencement et aménagement construction | C24: =+D54 -> 26358.5 | D24: =+C24/$C$32 -> 0.043930829
A25: Matériels industriels | C25: =+D40 -> 253709.4 | D25: =+C25/$C$32 -> 0.42284895
A26: Matériels de transport | C26: =+D45 -> 97000 | D26: =+C26/$C$32 -> 0.16166665
A27: Matériels et mobiliers de bureau | C27: 12000 | D27: =+C27/$C$32 -> 0.019999998
A28: Autres matériels | C28: 3500 | D28: =+C28/$C$32 -> 0.0058333327
A29: Sous-total Immobilisations Corporelles | C29: =SUM(C24:C28) -> 392567.9 | D29: =+C29/$C$32 -> 0.65427976
A30: Frais préliminaires | C30: =+D61 -> 20500 | D30: =+C30/$C$32 -> 0.034166663
A31: Fonds de roulement | C31: =+ACTIFS!D27+ACTIFS!D31+ACTIFS!D35-PASSIFS!D34-PASSIFS!D35 -> 181932.16 | D31: =+C31/$C$32 -> 0.30322024 | F31: =+C31/TVA!D3*360 -> 35.464525 | G31: j de CA TTC
A32: Total | C32: =++C31+C30+C29+C23 -> 600000.06 | D32: =+C32/$C$32 -> 1
A34: Matériels industriels | B34: Quantité | C34: Valeur en USD | D34: Valeur en DT | E34: % | F34: Capacité de production Kg/H | G34: Capacité annuelle en Kg(8H/j) | H34: Production prévue 2016
A35: Machine d'Emballage Vertical | B35: 1 | C35: 53000 | D35: =+C35*2.083 -> 110399 | E35: =+D35/$D$40 -> 0.43513957 | F35: =6*60 -> 360 | G35: =+F35*8*26*12 -> 898560 | H35: =+'Consommations Q'!$C$11 -> 133285.16 | I35: =+H35/G35 -> 0.14833195
A36: Machines à Rôtir OS190 | B36: 2 | C36: 36000 | D36: =+C36*2.083 -> 74988 | E36: =+D36/$D$40 -> 0.2955665 | F36: =50*2 -> 100 | G36: =+F36*8*26*12 -> 249600 | H36: =+'Consommations Q'!$C$11 -> 133285.16 | I36: =+H36/G36 -> 0.53399504
A37: Machine à Salage | B37: 1 | C37: 5300 | D37: =+C37*2.083 -> 11039.9 | E37: =+D37/$D$40 -> 0.043513957 | F37: =40*4 -> 160 | G37: =+F37*8*26*12 -> 399360 | H37: =+'Consommations Q'!$C$11 -> 133285.16 | I37: =+H37/G37 -> 0.3337469
A38: Machine Dragée | B38: 3 | C38: 20000 | D38: =+C38*2.083 -> 41660 | E38: =+D38/$D$40 -> 0.16420361 | F38: 50 | G38: =+(F38*8*26*12)*4 -> 499200 | H38: =+'Consommations Q'!$C$11 -> 133285.16 | I38: =+H38/G38 -> 0.26699752
A39: Machine d'épluchage de noisette et cacahuète | B39: 1 | C39: 7500 | D39: =+C39*2.083 -> 15622.5 | E39: =+D39/$D$40 -> 0.061576355 | F39: 250 | G39: =+F39*8*26*12 -> 624000 | H39: =+'Consommations Q'!$C$11 -> 133285.16 | I39: =+H39/G39 -> 0.21359801
C40: =SUM(C35:C39) -> 121800 | D40: =SUM(D35:D39) -> 253709.4 | E40: =SUM(E35:E39) -> 1
A42: Matériels de transport | B42: Quantité | D42: Valeur en DT
A43: Fourgon (Jumper) | B43: 1 | D43: 45000
A44: Fourgonnette (Berlinguo) | B44: 2 | D44: 52000
D45: =SUM(D43:D44) -> 97000
A47: Agencement et aménagements construction | D47: Valeur en DT
A48: Climatisations | D48: 5700
A49: Installations Eléctricité | D49: 6500
...

Sheet Prix achat-ventes
A1: Désignation de la rubrique | B1: Prix d'achat Kg | C1: Prix de vente Kg | D1: Prix de vente revendeur en sachet | E1: Prix marché sachet
A2: PF Mais | B2: =+Données!B28 -> 2.8 | C2: =+D2*10 -> 10 | D2: 1 | E2: 1
A3: PF Cacahuète | B3: =+Données!B29 -> 5.1 | C3: =+D3*10 -> 14 | D3: 1.4 | E3: 1.9
A4: PF Pois chiche | B4: =+Données!B30 -> 3.8 | C4: =+D4*10 -> 12 | D4: 1.2 | E4: 1.25
A5: PF Noisette | B5: =+Données!B34 -> 24 | C5: =+D5*10 -> 35 | D5: 3.5 | E5: 3
A6: PF Pistache | B6: =+Données!B33 -> 24 | C6: =+D6*10 -> 35 | D6: 3.5 | E6: 3.7
A7: PF Noix de Cajou | B7: =+Données!B32 -> 22 | C7: =+D7*10 -> 35 | D7: 3.5 | E7: 3.7
A8: PF Amande | B8: =+Données!B31 -> 25 | C8: =+D8*10 -> 35 | D8: 3.5 | E8: 3.7

Sheet Chiffre d'affaire
J1: 2016 | K1: 2017 | M1: 2018 | O1: 2019 | Q1: 2020 | S1: 2021 | U1: 2022
A2: Désignation de la rubrique | B2: QT produites en Kg/mois | C2: QT - sachet/mois | D2: PX UNIT | E2: CA Global mensuelle | F2: QT annuelle en Kg | G2: CA Annuelle/Sachet | H2: Ristourne 10% | I2: CA Net | J2: QT Annuel /Sachet | K2: QT Annuel /Sachet | L2: Valeurs | M2: QT Annuel /Sachet | N2: Valeurs | O2: QT Annuel /Sachet | P2: Valeurs | Q2: QT Annuel /Sachet | R2: Valeurs | S2: QT Annuel /Sachet | T2: Valeurs | U2: QT Annuel /Sachet | V2: Valeurs
A3: PF Mais | B3: 3120 | C3: =+B3*10 -> 31200 | D3: 1 | E3: =+C3*D3 -> 31200 | F3: =+B3*12 -> 37440 | G3: =+E3*12 -> 374400 | H3: =+G3*0.1 -> 37440 | I3: =+G3-H3 -> 336960 | J3: =+C3*12 -> 374400 | K3: =+J3*1.15 -> 430560 | L3: =+(K3*D3)*0.9 -> 387504 | M3: =+K3*1.15 -> 495144 | N3: =+(M3*D3)*0.9 -> 445629.6 | O3: =+M3*1.15 -> 569415.6 | P3: =+(O3*D3)*0.9 -> 512474.04 | Q3: =+O3*1.15 -> 654827.94 | R3: =+(Q3*D3)*0.9 -> 589345.15 | S3: =+Q3 -> 654827.94 | T3: =+(S3*D3)*0.9 -> 589345.15 | U3: =+S3 -> 654827.94 | V3: =+(U3*D3)*0.9 -> 589345.15
A4: PF Cacahuète | B4: 3120 | C4: =+B4*10 -> 31200 | D4: 1.4 | E4: =+C4*D4 -> 43680 | F4: =+B4*12 -> 37440 | G4: =+E4*12 -> 524160 | H4: =+G4*0.1 -> 52416 | I4: =+G4-H4 -> 471744 | J4: =+C4*12 -> 374400 | K4: =+J4*1.15 -> 430560 | L4: =+(K4*D4)*0.9 -> 542505.6 | M4: =+K4*1.15 -> 495144 | N4: =+(M4*D4)*0.9 -> 623881.44 | O4: =+M4*1.15 -> 569415.6 | P4: =+(O4*D4)*0.9 -> 717463.66 | Q4: =+O4*1.15 -> 654827.94 | R4: =+(Q4*D4)*0.9 -> 825083.2 | S4: =+Q4 -> 654827.94 | T4: =+(S4*D4)*0.9 -> 825083.2 | U4: =+S4 -> 654827.94 | V4: =+(U4*D4)*0.9 -> 825083.2
A5: PF Pois chiche | B5: 3120 | C5: =+B5*10 -> 31200 | D5: 1.2 | E5: =+C5*D5 -> 37440 | F5: =+B5*12 -> 37440 | G5: =+E5*12 -> 449280 | H5: =+G5*0.1 -> 44928 | I5: =+G5-H5 -> 404352 | J5: =+C5*12 -> 374400 | K5: =+J5*1.15 -> 430560 | L5: =+(K5*D5)*0.9 -> 465004.8 | M5: =+K5*1.15 -> 495144 | N5: =+(M5*D5)*0.9 -> 534755.52 | O5: =+M5*1.15 -> 569415.6 | P5: =+(O5*D5)*0.9 -> 614968.85 | Q5: =+O5*1.15 -> 654827.94 | R5: =+(Q5*D5)*0.9 -> 707214.18 | S5: =+Q5 -> 654827.94 | T5: =+(S5*D5)*0.9 -> 707214.18 | U5: =+S5 -> 654827.94 | V5: =+(U5*D5)*0.9 -> 707214.18
A6: PF noisette | B6: 350 | C6: =+B6*10 -> 3500 | D6: 3.5 | E6: =+C6*D6 -> 12250 | F6: =+B6*12 -> 4200 | G6: =+E6*12 -> 147000 | H6: =+G6*0.1 -> 14700 | I6: =+G6-H6 -> 132300 | J6: =+C6*12 -> 42000 | K6: =+J6*1.15 -> 48300 | L6: =+(K6*D6)*0.9 -> 152145 | M6: =+K6*1.15 -> 55545 | N6: =+(M6*D6)*0.9 -> 174966.75 | O6: =+M6*1.15 -> 63876.75 | P6: =+(O6*D6)*0.9 -> 201211.76 | Q6: =+O6*1.15 -> 73458.262 | R6: =+(Q6*D6)*0.9 -> 231393.53 | S6: =+Q6 -> 73458.262 | T6: =+(S6*D6)*0.9 -> 231393.53 | U6: =+S6 -> 73458.262 | V6: =+(U6*D6)*0.9 -> 231393.53
A7: PF pistche | B7: 350 | C7: =+B7*10 -> 3500 | D7: 3.5 | E7: =+C7*D7 -> 12250 | F7: =+B7*12 -> 4200 | G7: =+E7*12 -> 147000 | H7: =+G7*0.1 -> 14700 | I7: =+G7-H7 -> 132300 | J7: =+C7*12 -> 42000 | K7: =+J7*1.15 -> 48300 | L7: =+(K7*D7)*0.9 -> 152145 | M7: =+K7*1.15 -> 55545 | N7: =+(M7*D7)*0.9 -> 174966.75 | O7: =+M7*1.15 -> 63876.75 | P7: =+(O7*D7)*0.9 -> 201211.76 | Q7: =+O7*1.15 -> 73458.262 | R7: =+(Q7*D7)*0.9 -> 231393.53 | S7: =+Q7 -> 73458.262 | T7: =+(S7*D7)*0.9 -> 231393.53 | U7: =+S7 -> 73458.262 | V7: =+(U7*D7)*0.9 -> 231393.53
A8: PF acajou | B8: 350 | C8: =+B8*10 -> 3500 | D8: 3.5 | E8: =+C8*D8 -> 12250 | F8: =+B8*12 -> 4200 | G8: =+E8*12 -> 147000 | H8: =+G8*0.1 -> 14700 | I8: =+G8-H8 -> 132300 | J8: =+C8*12 -> 42000 | K8: =+J8*1.15 -> 48300 | L8: =+(K8*D8)*0.9 -> 152145 | M8: =+K8*1.15 -> 55545 | N8: =+(M8*D8)*0.9 -> 174966.75 | O8: =+M8*1.15 -> 63876.75 | P8: =+(O8*D8)*0.9 -> 201211.76 | Q8: =+O8*1.15 -> 73458.262 | R8: =+(Q8*D8)*0.9 -> 231393.53 | S8: =+Q8 -> 73458.262 | T8: =+(S8*D8)*0.9 -> 231393.53 | U8: =+S8 -> 73458.262 | V8: =+(U8*D8)*0.9 -> 231393.53
A9: PF Amande | B9: 350 | C9: =+B9*10 -> 3500 | D9: 3.5 | E9: =+C9*D9 -> 12250 | F9: =+B9*12 -> 4200 | G9: =+E9*12 -> 147000 | H9: =+G9*0.1 -> 14700 | I9: =+G9-H9 -> 132300 | J9: =+C9*12 -> 42000 | K9: =+J9*1.15 -> 48300 | L9: =+(K9*D9)*0.9 -> 152145 | M9: =+K9*1.15 -> 55545 | N9: =+(M9*D9)*0.9 -> 174966.75 | O9: =+M9*1.15 -> 63876.75 | P9: =+(O9*D9)*0.9 -> 201211.76 | Q9: =+O9*1.15 -> 73458.262 | R9: =+(Q9*D9)*0.9 -> 231393.53 | S9: =+Q9 -> 73458.262 | T9: =+(S9*D9)*0.9 -> 231393.53 | U9: =+S9 -> 73458.262 | V9: =+(U9*D9)*0.9 -> 231393.53
B10: =SUM(B3:B9) -> 10760 | C10: =SUM(C3:C9) -> 107600 | E10: =SUM(E3:E9) -> 161320 | F10: =SUM(F3:F9) -> 129120 | G10: =SUM(G3:G9) -> 1935840 | H10: =SUM(H3:H9) -> 193584 | I10: =SUM(I3:I9) -> 1742256 | J10: =SUM(J3:J9) -> 1291200 | K10: =SUM(K3:K9) -> 1484880 | L10: =SUM(L3:L9) -> 2003594.4 | ... V10: =SUM(V3:V9) -> 3047216.6
C11: =+C10*12 -> 1291200
K12: =+(K10-J10)/J10 -> 0.15 | M12: =+(M10-K10)/K10 -> 0.15 | N12: =+(N10-L10)/L10 -> 0.15 | O12: =+(O10-M10)/M10 -> 0.15 | P12: =+(P10-N10)/N10 -> 0.15 | Q12: =+(Q10-O10)/O10 -> 0.15 | R12: =+(R10-P10)/P10 -> 0.15 | S12: =+(S10-Q10)/Q10 -> 0 | T12: =+(T10-R10)/R10 -> 0 | V12: =+(V10-T10)/T10 -> 0
I13: Chiffre d'affaire y compris ristoune | N13: =+N10/0.9 -> 2560148.4 | P13: =+P10/0.9 -> 2944170.7 | R13: =+R10/0.9 -> 3385796.3 | T13: =+T10/0.9 -> 3385796.3
A17: Superette | B17: 100 | C17: =30*360*B17 -> 1080000 | D17: =+(C17/36)/100 -> 300
A18: Hotels | B18: 10 | C18: =100*360*B18 -> 360000 | D18: =+(C18/36)/100 -> 100
C19: =SUM(C17:C18) -> 1440000
A23: Produits | C23: Capacité de Ption annuelle
A24: Mais | B24: =+B3/$B$10 -> 0.28996283 | C24: =+B24*Investissements!$G$36*10 -> 723747.21
A25: Cacahuète | B25: =+B4/$B$10 -> 0.28996283 | C25: =+B25*Investissements!$G$36*10 -> 723747.21
A26: Pois chiche | B26: =+B5/$B$10 -> 0.28996283 | C26: =+B26*Investissements!$G$36*10 -> 723747.21
A27: Noisette | B27: =+B6/$B$10 -> 0.032527881 | C27: =+B27*Investissements!$G$36*10 -> 81189.591
A28: Pistche | B28: =+B7/$B$10 -> 0.032527881 | C28: =+B28*Investissements!$G$36*10 -> 81189.591
A29: Noix de Cajou | B29: =+B8/$B$10 -> 0.032527881 | C29: =+B29*Investissements!$G$36*10 -> 81189.591
A30: Amande | B30: =+B9/$B$10 -> 0.032527881 | C30: =+B30*Investissements!$G$36*10 -> 81189.591
B31: =SUM(B24:B30) -> 1 | C31: =SUM(C24:C30) -> 2496000
A34: Produits | B34: 2016 | C34: 2017 | D34: 2018 | E34: 2019 | F34: 2020 | G34: 2021 | H34: 2022
A35: Niveau de production/Capacité de production | B35: =+'Consommations Q'!C11*10/C31 -> 0.53399504 | C35: =+B35*1.15 -> 0.61409429 | D35: =+C35*1.15 -> 0.70620844 | E35: =+D35*1.15 -> 0.8121397 | F35: =+E35*1.15 -> 0.93396066 | G35: =+F35 -> 0.93396066 | H35: =+G35 -> 0.93396066
A36: Mais | B36: =+I3 -> 336960 | C36: =+L3 -> 387504 | D36: =+N3 -> 445629.6 | E36: =+P3 -> 512474.04 | F36: =+R3 -> 589345.15 | G36: =+T3 -> 589345.15 | H36: =+G36 -> 589345.15
A37: Cacahuète | B37: =+I4 -> 471744 | C37: =+L4 -> 542505.6 | D37: =+N4 -> 623881.44 | E37: =+P4 -> 717463.66 | F37: =+R4 -> 825083.2 | G37: =+T4 -> 825083.2 | H37: =+G37 -> 825083.2
A38: Pois chiche | B38: =+I5 -> 404352 | C38: =+L5 -> 465004.8 | D38: =+N5 -> 534755.52 | E38: =+P5 -> 614968.85 | F38: =+R5 -> 707214.18 | G38: =+T5 -> 707214.18 | H38: =+G38 -> 707214.18
A39: Noisette | B39: =+I6 -> 132300 | C39: =+L6 -> 152145 | D39: =+N6 -> 174966.75 | E39: =+P6 -> 201211.76 | F39: =+R6 -> 231393.53 | G39: =+T6 -> 231393.53 | H39: =+G39 -> 231393.53
A40: Pistche | B40: =+I7 -> 132300 | C40: =+L7 -> 152145 | D40: =+N7 -> 174966.75 | E40: =+P7 -> 201211.76 | F40: =+R7 -> 231393.53 | G40: =+T7 -> 231393.53 | H40: =+G40 -> 231393.53
A41: Noix de Cajou | B41: =+I8 -> 132300 | C41: =+L8 -> 152145 | D41: =+N8 -> 174966.75 | E41: =+P8 -> 201211.76 | F41: =+R8 -> 231393.53 | G41: =+T8 -> 231393.53 | H41: =+G41 -> 231393.53
A42: Amande | B42: =+I9 -> 132300 | C42: =+L9 -> 152145 | D42: =+N9 -> 174966.75 | E42: =+P9 -> 201211.76 | F42: =+R9 -> 231393.53 | G42: =+T9 -> 231393.53 | H42: =+G42 -> 231393.53
B43: =SUM(B36:B42) -> 1742256 | C43: =SUM(C36:C42) -> 2003594.4 | D43: =SUM(D36:D42) -> 2304133.6 | E43: =SUM(E36:E42) -> 2649753.6 | F43: =SUM(F36:F42) -> 3047216.6 | G43: =SUM(G36:G42) -> 3047216.6 | H43: =SUM(H36:H42) -> 3047216.6
B44: =+B43-'P&L'!C10 -> 0 | C44: =+C43-'P&L'!E10 -> 0 | D44: =+D43-'P&L'!G10 -> 0 | E44: =+E43-'P&L'!I10 -> 0 | F44: =+F43-'P&L'!K10 -> 0
B48: 2016 | D48: 2017 | F48: 2018 | H48: 2019 | J48: 2020 | L48: 2021 | N48: 2022
A49: Produits | B49: QT Annuel /Sachet | C49: Valeurs | D49: QT Annuel /Sachet | E49: Valeurs | F49: QT Annuel /Sachet | G49: Valeurs | H49: QT Annuel /Sachet | I49: Valeurs | J49: QT Annuel /Sachet | K49: Valeurs | L49: QT Annuel /Sachet | M49: Valeurs | N49: QT Annuel /Sachet | O49: Valeurs
A50: Mais | B50: 374400 | C50: 336960 | D50: 430560 | E50: 387504 | F50: 495144 | G50: 445629.6 | H50: 569415.6 | I50: 512474.04 | J50: 654827.94 | K50: 589345.15 | L50: 654827.94 | M50: 589345.15 | N50: 654827.94 | O50: 589345.15
A51: Cacahuète | B51: 374400 | C51: 471744 | D51: 430560 | E51: 542505.6 | F51: 495144 | G51: 623881.44 | H51: 569415.6 | I51: 717463.66 | J51: 654827.94 | K51: 825083.2 | L51: 654827.94 | M51: 825083.2 | N51: 654827.94 | O51: 825083.2
...

Sheet Calcul Coût Ption
A1: Désignation de la rubrique | B1: QT annuelle en Kg | C1: Cout de Production | D1: Q st final | E1: Valeur stock final
A2: PF Mais aromatisés | B2: =+'Chiffre d''affaire'!F3+('Chiffre d''affaire'!F3/310*10) -> 38647.742 | C2: =+B23 -> 5.8884015 | D2: =+B2-'Chiffre d''affaire'!F3 -> 1207.7419 | E2: =+D2*C2 -> 7111.6695
A3: PF Cacahuète aromatisés | B3: =+'Chiffre d''affaire'!F4+('Chiffre d''affaire'!F4/310*10) -> 38647.742 | C3: =+C23 -> 8.3114015 | D3: =+B3-'Chiffre d''affaire'!F4 -> 1207.7419 | E3: =+D3*C3 -> 10038.028
A4: PF Pois chiche aromatisés | B4: =+'Chiffre d''affaire'!F5+('Chiffre d''affaire'!F5/310*10) -> 38647.742 | C4: =+D23 -> 6.9484015 | D4: =+B4-'Chiffre d''affaire'!F5 -> 1207.7419 | E4: =+D4*C4 -> 8391.8759
A5: PF noisette | B5: =+'Chiffre d''affaire'!F6+('Chiffre d''affaire'!F6/310*10) -> 4335.4839 | C5: =+E23 -> 27.925402 | D5: =+B5-'Chiffre d''affaire'!F6 -> 135.48387 | E5: =+D5*C5 -> 3783.4415
A6: PF pistche | B6: =+'Chiffre d''affaire'!F7+('Chiffre d''affaire'!F7/310*10) -> 4335.4839 | C6: =+F23 -> 27.925402 | D6: =+B6-'Chiffre d''affaire'!F7 -> 135.48387 | E6: =+D6*C6 -> 3783.4415
A7: PF acajou | B7: =+'Chiffre d''affaire'!F8+('Chiffre d''affaire'!F8/310*10) -> 4335.4839 | C7: =+G23 -> 25.905402 | D7: =+B7-'Chiffre d''affaire'!F8 -> 135.48387 | E7: =+D7*C7 -> 3509.7641
A8: PF Amande | B8: =+'Chiffre d''affaire'!F9+('Chiffre d''affaire'!F9/310*10) -> 4335.4839 | C8: =+H23 -> 28.935402 | D8: =+B8-'Chiffre d''affaire'!F9 -> 135.48387 | E8: =+D8*C8 -> 3920.2802
B9: =SUM(B2:B8) -> 133285.16 | D9: =SUM(D2:D8) -> 4165.1613 | E9: =SUM(E2:E8) -> 40538.501
B12: PF Mais | C12: PF Cacahuète | D12: PF Pois chiche | E12: PF noisette | F12: PF pistche | G12: PF acajou | H12: PF amande
A13: Calcul cout de production2016
A14: Achat MP | B14: ='Achat Matière'!C3 -> 2.8 | C14: =+'Achat Matière'!C4 -> 5.1 | D14: =+'Achat Matière'!C5 -> 3.8 | E14: =+'Achat Matière'!C6 -> 24 | F14: =+'Achat Matière'!C7 -> 24 | G14: =+'Achat Matière'!C8 -> 22 | H14: =+'Achat Matière'!C9 -> 25
A15: Achats Aromes | B15: =+Données!$B$35/1000*60 -> 1.33098 | C15: =+Données!$B$35/1000*60 -> 1.33098 | D15: =+Données!$B$35/1000*60 -> 1.33098 | E15: =+Données!$B$35/1000*60 -> 1.33098 | F15: =+Données!$B$35/1000*60 -> 1.33098 | G15: =+Données!$B$35/1000*60 -> 1.33098 | H15: =+Données!$B$35/1000*60 -> 1.33098
A16: Achat emballage | B16: =+'Achat Matière'!$F$14/1000*50 -> 0.55 | C16: =+'Achat Matière'!$F$14/1000*50 -> 0.55 | D16: =+'Achat Matière'!$F$14/1000*50 -> 0.55 | E16: =+'Achat Matière'!$F$14/1000*50 -> 0.55 | F16: =+'Achat Matière'!$F$14/1000*50 -> 0.55 | G16: =+'Achat Matière'!$F$14/1000*50 -> 0.55 | H16: =+'Achat Matière'!$F$14/1000*50 -> 0.55
A17: Gaz | B17: =+'Chiffre d''affaire'!D3*10*0.01 -> 0.1 | C17: =+'Chiffre d''affaire'!D4*10*0.01 -> 0.14 | D17: =+'Chiffre d''affaire'!D5*10*0.01 -> 0.12 | E17: =+'Chiffre d''affaire'!D6*10*0.01 -> 0.35 | F17: =+'Chiffre d''affaire'!$D$7*10*0.01 -> 0.35 | G17: =+'Chiffre d''affaire'!$D$8*10*0.01 -> 0.35 | H17: =+'Chiffre d''affaire'!$D$9*10*0.01 -> 0.35
A18: Electricité | B18: =+'Chiffre d''affaire'!D3*10*0.01 -> 0.1 | C18: =+'Chiffre d''affaire'!D4*10*0.01 -> 0.14 | D18: =+'Chiffre d''affaire'!D5*10*0.01 -> 0.12 | E18: =+'Chiffre d''affaire'!D6*10*0.01 -> 0.35 | F18: =+'Chiffre d''affaire'!$D$7*10*0.01 -> 0.35 | G18: =+'Chiffre d''affaire'!$D$8*10*0.01 -> 0.35 | H18: =+'Chiffre d''affaire'!$D$9*10*0.01 -> 0.35
A19: Eau | B19: =+'Chiffre d''affaire'!D3*10*0.005 -> 0.05 | C19: =+'Chiffre d''affaire'!D4*10*0.005 -> 0.07 | D19: =+'Chiffre d''affaire'!D5*10*0.005 -> 0.06 | E19: =+'Chiffre d''affaire'!D6*10*0.005 -> 0.175 | F19: =+'Chiffre d''affaire'!$D$7*10*0.005 -> 0.175 | G19: =+'Chiffre d''affaire'!$D$8*10*0.005 -> 0.175 | H19: =+'Chiffre d''affaire'!$D$9*10*0.005 -> 0.175
A20: Main d'œuvre | B20: =+SALAIRE!$C$27 -> 0.73907072 | C20: =+SALAIRE!$C$27 -> 0.73907072 | D20: =+SALAIRE!$C$27 -> 0.73907072 | E20: =+SALAIRE!$C$27 -> 0.73907072 | F20: =+SALAIRE!$C$27 -> 0.73907072 | G20: =+SALAIRE!$C$27 -> 0.73907072 | H20: =+SALAIRE!$C$27 -> 0.73907072
A21: Amortissement machine | B21: =+Investissements!$F$6/'Calcul Coût Ption'!$B$9 -> 0.19035082 | C21: =+Investissements!$F$6/'Calcul Coût Ption'!$B$9 -> 0.19035082 | D21: =+Investissements!$F$6/'Calcul Coût Ption'!$B$9 -> 0.19035082 | E21: =+Investissements!$F$6/'Calcul Coût Ption'!$B$9 -> 0.19035082 | F21: =+Investissements!$F$6/'Calcul Coût Ption'!$B$9 -> 0.19035082 | G21: =+Investissements!$F$6/'Calcul Coût Ption'!$B$9 -> 0.19035082 | H21: =+Investissements!$F$6/'Calcul Coût Ption'!$B$9 -> 0.19035082
A22: Dechets(1%) | B22: =1%*B14 -> 0.028 | C22: =1%*C14 -> 0.051 | D22: =1%*D14 -> 0.038 | E22: =1%*E14 -> 0.24 | F22: =1%*F14 -> 0.24 | G22: =1%*G14 -> 0.22 | H22: =1%*H14 -> 0.25
B23: =SUM(B14:B22) -> 5.8884015 | C23: =SUM(C14:C22) -> 8.3114015 | D23: =SUM(D14:D22) -> 6.9484015 | E23: =SUM(E14:E22) -> 27.925402 | F23: =SUM(F14:F22) -> 27.925402 | G23: =SUM(G14:G22) -> 25.905402 | H23: =SUM(H14:H22) -> 28.935402
A24: Prix de vente unitaire | B24: =+('Chiffre d''affaire'!D3*10)*0.9 -> 9 | C24: =+('Chiffre d''affaire'!D4*10)*0.9 -> 12.6 | D24: =+'Chiffre d''affaire'!D5*10*0.9 -> 10.8 | E24: =+'Chiffre d''affaire'!D6*10*0.9 -> 31.5 | F24: =+'Chiffre d''affaire'!D7*10*0.9 -> 31.5 | G24: =+'Chiffre d''affaire'!D8*10*0.9 -> 31.5 | H24: =+'Chiffre d''affaire'!D9*10*0.9 -> 31.5
A25: Marge/cout matière unit | B25: =+B24-SUM(B14:B19)-B22 -> 4.04102 | C25: =+C24-SUM(C14:C19)-C22 -> 5.21802 | D25: =+D24-SUM(D14:D19)-D22 -> 4.78102 | E25: =+E24-SUM(E14:E19)-E22 -> 4.50402 | F25: =+F24-SUM(F14:F19)-F22 -> 4.50402 | G25: =+G24-SUM(G14:G19)-G22 -> 6.52402 | H25: =+H24-SUM(H14:H19)-H22 -> 3.49402
A26: Taux de marge | B26: =+B25/B24 -> 0.44900222 | C26: =+C25/C24 -> 0.41412857 | D26: =+D25/D24 -> 0.44268704 | E26: =+E25/E24 -> 0.14298476 | F26: =+F25/F24 -> 0.14298476 | G26: =+G25/G24 -> 0.20711175 | H26: =+H25/H24 -> 0.11092127
B27: =+'Taux de marge'!G4 -> 0.45322954 | C27: =+'Taux de marge'!G5 -> 0.4174041 | D27: =+'Taux de marge'!G6 -> 0.44635914 | E27: =+'Taux de marge'!G7 -> 0.14483261 | F27: =+'Taux de marge'!G8 -> 0.14483261 | G27: =+'Taux de marge'!G9 -> 0.20895959 | H27: =+'Taux de marge'!G10 -> 0.11276912

Sheet Cout de production prévisionnel
B1: 2016 | F1: 2017 | J1: 2018 | N1: 2019 | R1: 2020 | V1: 2021 | Z1: 2022
A2: Désignation de la rubrique | B2: QT vendues annuelle en Kg | C2: Cout de Production | D2: Q st final | E2: Valeur stock final | F2: QT vendues annuelle en Kg | G2: Cout de Production | H2: Q st final | I2: Valeur stock final | J2: QT vendues annuelle en Kg | K2: Cout de Production | L2: Q st final | M2: Valeur stock final | N2: QT vendues annuelle en Kg | O2: Cout de Production | P2: Q st final | Q2: Valeur stock final | R2: QT vendues annuelle en Kg | S2: Cout de Production | T2: Q st final | U2: Valeur stock final | V2: QT vendues annuelle en Kg | W2: Cout de Production | X2: Q st final | Y2: Valeur stock final | Z2: QT vendues annuelle en Kg | AA2: Cout de Production | AB2: Q st final | AC2: Valeur stock final
A3: PF Mais aromatisés | B3: =+'Consommations Q'!B4 -> 37440 | C3: =+'Calcul Coût Ption'!C2 -> 5.8884015 | D3: =+B3/310*10 -> 1207.7419 | E3: =+C3*D3 -> 7111.6695 | F3: =+'Consommations Q'!G4 -> 43056 | G3: =+C3 -> 5.8884015 | H3: =+F3/310*10 -> 1388.9032 | I3: =+G3*H3 -> 8178.4199 | J3: =+'Consommations Q'!L4 -> 49514.4 | K3: =+G3 -> 5.8884015 | L3: =+J3/310*10 -> 1597.2387 | M3: =+K3*L3 -> 9405.1829 | N3: =+'Consommations Q'!Q4 -> 56941.56 | O3: =+K3 -> 5.8884015 | P3: =+N3/310*10 -> 1836.8245 | Q3: =+O3*P3 -> 10815.96 | R3: =+'Consommations Q'!V4 -> 65482.794 | S3: =+O3 -> 5.8884015 | T3: =+R3/310*10 -> 2112.3482 | U3: =+S3*T3 -> 12438.354 | V3: =+'Consommations Q'!AA4 -> 65482.794 | W3: =+S3 -> 5.8884015 | X3: =+V3/310*10 -> 2112.3482 | Y3: =+W3*X3 -> 12438.354 | Z3: =+'Consommations Q'!AF4 -> 65482.794 | AA3: =+W3 -> 5.8884015 | AB3: =+Z3/310*10 -> 2112.3482 | AC3: =+AA3*AB3 -> 12438.354
A4: PF Cacahuète aromatisés | B4: =+'Consommations Q'!B5 -> 37440 | C4: =+'Calcul Coût Ption'!C3 -> 8.3114015 | D4: =+B4/310*10 -> 1207.7419 | E4: =+C4*D4 -> 10038.028 | F4: =+'Consommations Q'!G5 -> 43056 | G4: =+C4 -> 8.3114015 | H4: =+F4/310*10 -> 1388.9032 | I4: =+G4*H4 -> 11543.732 | J4: =+'Consommations Q'!L5 -> 49514.4 | K4: =+G4 -> 8.3114015 | L4: =+J4/310*10 -> 1597.2387 | M4: =+K4*L4 -> 13275.292 | N4: =+'Consommations Q'!Q5 -> 56941.56 | O4: =+K4 -> 8.3114015 | P4: =+N4/310*10 -> 1836.8245 | Q4: =+O4*P4 -> 15266.586 | R4: =+'Consommations Q'!V5 -> 65482.794 | S4: =+O4 -> 8.3114015 | T4: =+R4/310*10 -> 2112.3482 | U4: =+S4*T4 -> 17556.574 | V4: =+'Consommations Q'!AA5 -> 65482.794 | W4: =+S4 -> 8.3114015 | X4: =+V4/310*10 -> 2112.3482 | Y4: =+W4*X4 -> 17556.574 | Z4: =+'Consommations Q'!AF5 -> 65482.794 | AA4: =+W4 -> 8.3114015 | AB4: =+Z4/310*10 -> 2112.3482 | AC4: =+AA4*AB4 -> 17556.574
A5: PF Pois chiche aromatisés | B5: =+'Consommations Q'!B6 -> 37440 | C5: =+'Calcul Coût Ption'!C4 -> 6.9484015 | D5: =+B5/310*10 -> 1207.7419 | E5: =+C5*D5 -> 8391.8759 | F5: =+'Consommations Q'!G6 -> 43056 | G5: =+C5 -> 6.9484015 | H5: =+F5/310*10 -> 1388.9032 | I5: =+G5*H5 -> 9650.6573 | J5: =+'Consommations Q'!L6 -> 49514.4 | K5: =+G5 -> 6.9484015 | L5: =+J5/310*10 -> 1597.2387 | M5: =+K5*L5 -> 11098.256 | N5: =+'Consommations Q'!Q6 -> 56941.56 | O5: =+K5 -> 6.9484015 | P5: =+N5/310*10 -> 1836.8245 | Q5: =+O5*P5 -> 12762.994 | R5: =+'Consommations Q'!V6 -> 65482.794 | S5: =+O5 -> 6.9484015 | T5: =+R5/310*10 -> 2112.3482 | U5: =+S5*T5 -> 14677.443 | V5: =+'Consommations Q'!AA6 -> 65482.794 | W5: =+S5 -> 6.9484015 | X5: =+V5/310*10 -> 2112.3482 | Y5: =+W5*X5 -> 14677.443 | Z5: =+'Consommations Q'!AF6 -> 65482.794 | AA5: =+W5 -> 6.9484015 | AB5: =+Z5/310*10 -> 2112.3482 | AC5: =+AA5*AB5 -> 14677.443
A6: PF noisette | B6: =+'Consommations Q'!B7 -> 4200 | C6: =+'Calcul Coût Ption'!C5 -> 27.925402 | D6: =+B6/310*10 -> 135.48387 | E6: =+C6*D6 -> 3783.4415 | F6: =+'Consommations Q'!G7 -> 4830 | G6: =+C6 -> 27.925402 | H6: =+F6/310*10 -> 155.80645 | I6: =+G6*H6 -> 4350.9577 | J6: =+'Consommations Q'!L7 -> 5554.5 | K6: =+G6 -> 27.925402 | L6: =+J6/310*10 -> 179.17742 | M6: =+K6*L6 -> 5003.6014 | N6: =+'Consommations Q'!Q7 -> 6387.675 | O6: =+K6 -> 27.925402 | P6: =+N6/310*10 -> 206.05403 | Q6: =+O6*P6 -> 5754.1416 | R6: =+'Consommations Q'!V7 -> 7345.8262 | S6: =+O6 -> 27.925402 | T6: =+R6/310*10 -> 236.96214 | U6: =+S6*T6 -> 6617.2628 | V6: =+'Consommations Q'!AA7 -> 7345.8262 | W6: =+S6 -> 27.925402 | X6: =+V6/310*10 -> 236.96214 | Y6: =+W6*X6 -> 6617.2628 | Z6: =+'Consommations Q'!AF7 -> 7345.8262 | AA6: =+W6 -> 27.925402 | AB6: =+Z6/310*10 -> 236.96214 | AC6: =+AA6*AB6 -> 6617.2628
A7: PF pistche | B7: =+'Consommations Q'!B8 -> 4200 | C7: =+'Calcul Coût Ption'!C6 -> 27.925402 | D7: =+B7/310*10 -> 135.48387 | E7: =+C7*D7 -> 3783.4415 | F7: =+'Consommations Q'!G8 -> 4830 | G7: =+C7 -> 27.925402 | H7: =+F7/310*10 -> 155.80645 | I7: =+G7*H7 -> 4350.9577 | J7: =+'Consommations Q'!L8 -> 5554.5 | K7: =+G7 -> 27.925402 | L7: =+J7/310*10 -> 179.17742 | M7: =+K7*L7 -> 5003.6014 | N7: =+'Consommations Q'!Q8 -> 6387.675 | O7: =+K7 -> 27.925402 | P7: =+N7/310*10 -> 206.05403 | Q7: =+O7*P7 -> 5754.1416 | R7: =+'Consommations Q'!V8 -> 7345.8262 | S7: =+O7 -> 27.925402 | T7: =+R7/310*10 -> 236.96214 | U7: =+S7*T7 -> 6617.2628 | V7: =+'Consommations Q'!AA8 -> 7345.8262 | W7: =+S7 -> 27.925402 | X7: =+V7/310*10 -> 236.96214 | Y7: =+W7*X7 -> 6617.2628 | Z7: =+'Consommations Q'!AF8 -> 7345.8262 | AA7: =+W7 -> 27.925402 | AB7: =+Z7/310*10 -> 236.96214 | AC7: =+AA7*AB7 -> 6617.2628
A8: PF acajou | B8: =+'Consommations Q'!B9 -> 4200 | C8: =+'Calcul Coût Ption'!C7 -> 25.905402 | D8: =+B8/310*10 -> 135.48387 | E8: =+C8*D8 -> 3509.7641 | F8: =+'Consommations Q'!G9 -> 4830 | G8: =+C8 -> 25.905402 | H8: =+F8/310*10 -> 155.80645 | I8: =+G8*H8 -> 4036.2287 | J8: =+'Consommations Q'!L9 -> 5554.5 | K8: =+G8 -> 25.905402 | L8: =+J8/310*10 -> 179.17742 | M8: =+K8*L8 -> 4641.663 | N8: =+'Consommations Q'!Q9 -> 6387.675 | O8: =+K8 -> 25.905402 | P8: =+N8/310*10 -> 206.05403 | Q8: =+O8*P8 -> 5337.9124 | R8: =+'Consommations Q'!V9 -> 7345.8262 | S8: =+O8 -> 25.905402 | T8: =+R8/310*10 -> 236.96214 | U8: =+S8*T8 -> 6138.5993 | V8: =+'Consommations Q'!AA9 -> 7345.8262 | W8: =+S8 -> 25.905402 | X8: =+V8/310*10 -> 236.96214 | Y8: =+W8*X8 -> 6138.5993 | Z8: =+'Consommations Q'!AF9 -> 7345.8262 | AA8: =+W8 -> 25.905402 | AB8: =+Z8/310*10 -> 236.96214 | AC8: =+AA8*AB8 -> 6138.5993
A9: PF Amande | B9: =+'Consommations Q'!B10 -> 4200 | C9: =+'Calcul Coût Ption'!C8 -> 28.935402 | D9: =+B9/310*10 -> 135.48387 | E9: =+C9*D9 -> 3920.2802 | F9: =+'Consommations Q'!G10 -> 4830 | G9: =+C9 -> 28.935402 | H9: =+F9/310*10 -> 155.80645 | I9: =+G9*H9 -> 4508.3222 | J9: =+'Consommations Q'!L10 -> 5554.5 | K9: =+G9 -> 28.935402 | L9: =+J9/310*10 -> 179.17742 | M9: =+K9*L9 -> 5184.5706 | N9: =+'Consommations Q'!Q10 -> 6387.675 | O9: =+K9 -> 28.935402 | P9: =+N9/310*10 -> 206.05403 | Q9: =+O9*P9 -> 5962.2562 | R9: =+'Consommations Q'!V10 -> 7345.8262 | S9: =+O9 -> 28.935402 | T9: =+R9/310*10 -> 236.96214 | U9: =+S9*T9 -> 6856.5946 | V9: =+'Consommations Q'!AA10 -> 7345.8262 | W9: =+S9 -> 28.935402 | X9: =+V9/310*10 -> 236.96214 | Y9: =+W9*X9 -> 6856.5946 | Z9: =+'Consommations Q'!AF10 -> 7345.8262 | AA9: =+W9 -> 28.935402 | AB9: =+Z9/310*10 -> 236.96214 | AC9: =+AA9*AB9 -> 6856.5946
B10: =SUM(B3:B9) -> 129120 | D10: =SUM(D3:D9) -> 4165.1613 | E10: =SUM(E3:E9) -> 40538.501 | F10: =SUM(F3:F9) -> 148488 | H10: =SUM(H3:H9) -> 4789.9355 | I10: =SUM(I3:I9) -> 46619.276 | J10: =SUM(J3:J9) -> 170761.2 | K10: =SUM(K3:K9) -> 131.83981 | L10: =SUM(L3:L9) -> 5508.4258 | M10: =SUM(M3:M9) -> 53612.167 | N10: =SUM(N3:N9) -> 196375.38 | O10: =SUM(O3:O9) -> 131.83981 | ... AC10: =SUM(AC3:AC9) -> 70902.091
A12: Variation du Stock | E12: =0-E10 -> -40538.501 | I12: =+E10-I10 -> -6080.7751 | M12: =+I10-M10 -> -6992.8914 | Q12: =+M10-Q10 -> -8041.8251 | U12: =+Q10-U10 -> -9248.0989 | Y12: =+U10-Y10 -> 0 | AC12: =+Y10-AC10 -> 0
B14: 2016 | C14: 2017 | D14: 2018 | E14: 2019 | F14: 2020 | G14: 2021 | H14: 2022
A15: Désignation de la rubrique | B15: Qt matière consommées | C15: Qt matière consommées | D15: Qt matière consommées | E15: Qt matière consommées | F15: Qt matière consommées | G15: Qt matière consommées | H15: Qt matière consommées
A16: PF Mais aromatisés
A17: PF Cacahuète aromatisés
A18: PF Pois chiche aromatisés
A19: PF noisette
A20: PF pistche
A21: PF acajou
A22: PF Amande
B23: =SUM(B16:B22) -> 0 | C23: =SUM(C16:C22) -> 0 | D23: =SUM(D16:D22) -> 0 | E23: =SUM(E16:E22) -> 0 | F23: =SUM(F16:F22) -> 0 | G23: =SUM(G16:G22) -> 0 | H23: =SUM(H16:H22) -> 0

Sheet Taux de marge
A1: 2016
A3: Produits | B3: Chiffre d'affaire net | C3: Consommations matière | D3: Consommations Autres approv | E3: Variation St. P finis | F3: Marge Brut | G3: Taux de marge
A4: PF Mais | B4: =+'Chiffre d''affaire'!I3 -> 336960 | C4: =+(('Ach prévisionnel'!D3-'Ach prévisionnel'!F3)+('Ach prévisionnel'!D17+'Ach prévisionnel'!D30)) -> 181991.44 | D4: =+(B4/0.9)*0.025 -> 9360 | E4: =-'Cout de production prévisionnel'!E3 -> -7111.6695 | F4: =+(B4-(C4+D4+E4)) -> 152720.23 | G4: =+F4/B4 -> 0.45322954
A5: PF Cacahuète | B5: =+'Chiffre d''affaire'!I4 -> 471744 | C5: =+(('Ach prévisionnel'!D4-'Ach prévisionnel'!F4)+'Ach prévisionnel'!D18+'Ach prévisionnel'!D31) -> 271770.15 | D5: =+(B5/0.9)*0.025 -> 13104 | E5: =-'Cout de production prévisionnel'!E4 -> -10038.028 | F5: =+(B5-(C5+D5+E5)) -> 196907.88 | G5: =+F5/B5 -> 0.4174041
A6: PF Pois chiche | B6: =+'Chiffre d''affaire'!I5 -> 404352 | C6: =+('Ach prévisionnel'!D5-'Ach prévisionnel'!F5)+'Ach prévisionnel'!D19+'Ach prévisionnel'!D32 -> 221025.66 | D6: =+(B6/0.9)*0.025 -> 11232 | E6: =-'Cout de production prévisionnel'!E5 -> -8391.8759 | F6: =+(B6-(C6+D6+E6)) -> 180486.21 | G6: =+F6/B6 -> 0.44635914
A7: PF noisette | B7: =+'Chiffre d''affaire'!I6 -> 132300 | C7: =+('Ach prévisionnel'!D6-'Ach prévisionnel'!F6)+'Ach prévisionnel'!D20+'Ach prévisionnel'!D33 -> 113247.09 | D7: =+(B7/0.9)*0.025 -> 3675 | E7: =-'Cout de production prévisionnel'!E6 -> -3783.4415 | F7: =+(B7-(C7+D7+E7)) -> 19161.354 | G7: =+F7/B7 -> 0.14483261
A8: PF pistche | B8: =+'Chiffre d''affaire'!I7 -> 132300 | C8: =+('Ach prévisionnel'!D7-'Ach prévisionnel'!F7)+'Ach prévisionnel'!D21+'Ach prévisionnel'!D34 -> 113247.09 | D8: =+(B8/0.9)*0.025 -> 3675 | E8: =-'Cout de production prévisionnel'!E7 -> -3783.4415 | F8: =+(B8-(C8+D8+E8)) -> 19161.354 | G8: =+F8/B8 -> 0.14483261
A9: PF acajou | B9: =+'Chiffre d''affaire'!I8 -> 132300 | C9: =+('Ach prévisionnel'!D8-'Ach prévisionnel'!F8)+'Ach prévisionnel'!D22+'Ach prévisionnel'!D35 -> 104489.41 | D9: =+(B9/0.9)*0.025 -> 3675 | E9: =-'Cout de production prévisionnel'!E8 -> -3509.7641 | F9: =+(B9-(C9+D9+E9)) -> 27645.354 | G9: =+F9/B9 -> 0.20895959
A10: PF Amande | B10: =+'Chiffre d''affaire'!I9 -> 132300 | C10: =+('Ach prévisionnel'!D9-'Ach prévisionnel'!F9)+'Ach prévisionnel'!D23+'Ach prévisionnel'!D36 -> 117625.93 | D10: =+(B10/0.9)*0.025 -> 3675 | E10: =-'Cout de production prévisionnel'!E9 -> -3920.2802 | F10: =+(B10-(C10+D10+E10)) -> 14919.354 | G10: =+F10/B10 -> 0.11276912
B12: =SUM(B4:B11) -> 1742256 | C12: =SUM(C4:C11) -> 1123396.8 | D12: =SUM(D4:D11) -> 48396 | E12: =SUM(E4:E11) -> -40538.501 | F12: =SUM(F4:F11) -> 611001.73 | G12: =+F12/B12 -> 0.35069573 | I12: =SUM(C12:E12) -> 1131254.3
A14: 2017
A15: Produits | B15: Chiffre d'affaire | C15: Consommations matière | D15: Consommations Autres approv | E15: Variation St. P finis | F15: Marge Brut | G15: Taux de marge
A16: PF Mais | B16: =+'Chiffre d''affaire'!L3 -> 387504 | C16: =('Ach prévisionnel'!I3+'Ach prévisionnel'!F3-'Ach prévisionnel'!K3)+'Ach prévisionnel'!I17+'Ach prévisionnel'!I30 -> 203602.93 | D16: =+(B16/0.9)*0.025 -> 10764 | E16: =+'Cout de production prévisionnel'!E3-'Cout de production prévisionnel'!I3 -> -1066.7504 | F16: =+(B16-(C16+D16+E16)) -> 174203.82 | G16: =+F16/B16 -> 0.44955361
A17: PF Cacahuète | B17: =+'Chiffre d''affaire'!L4 -> 542505.6 | C17: =('Ach prévisionnel'!I4+'Ach prévisionnel'!F4-'Ach prévisionnel'!K4)+'Ach prévisionnel'!I18+'Ach prévisionnel'!I31 -> 304042.85 | D17: =+(B17/0.9)*0.025 -> 15069.6 | E17: =+'Cout de production prévisionnel'!E4-'Cout de production prévisionnel'!I4 -> -1505.7042 | F17: =+(B17-(C17+D17+E17)) -> 224898.85 | G17: =+F17/B17 -> 0.41455581
A18: PF Pois chiche | B18: =+'Chiffre d''affaire'!L5 -> 465004.8 | C18: =('Ach prévisionnel'!I5+'Ach prévisionnel'!F5-'Ach prévisionnel'!K5)+'Ach prévisionnel'!I19+'Ach prévisionnel'!I32 -> 247272.46 | D18: =+(B18/0.9)*0.025 -> 12916.8 | E18: =+'Cout de production prévisionnel'!E5-'Cout de production prévisionnel'!I5 -> -1258.7814 | F18: =+(B18-(C18+D18+E18)) -> 206074.32 | G18: =+F18/B18 -> 0.44316601
A19: PF noisette | B19: =+'Chiffre d''affaire'!L6 -> 152145 | C19: =('Ach prévisionnel'!I6+'Ach prévisionnel'!F6-'Ach prévisionnel'!K6)+'Ach prévisionnel'!I20+'Ach prévisionnel'!I33 -> 126695.18 | D19: =+(B19/0.9)*0.025 -> 4226.25 | E19: =+'Cout de production prévisionnel'!E6-'Cout de production prévisionnel'!I6 -> -567.51622 | F19: =+(B19-(C19+D19+E19)) -> 21791.087 | G19: =+F19/B19 -> 0.14322579
A20: PF pistche | B20: =+'Chiffre d''affaire'!L7 -> 152145 | C20: =('Ach prévisionnel'!I7+'Ach prévisionnel'!F7-'Ach prévisionnel'!K7)+'Ach prévisionnel'!I21+'Ach prévisionnel'!I34 -> 126695.18 | D20: =+(B20/0.9)*0.025 -> 4226.25 | E20: =+'Cout de production prévisionnel'!E7-'Cout de production prévisionnel'!I7 -> -567.51622 | F20: =+(B20-(C20+D20+E20)) -> 21791.087 | G20: =+F20/B20 -> 0.14322579
A21: PF acajou | B21: =+'Chiffre d''affaire'!L8 -> 152145 | C21: =('Ach prévisionnel'!I8+'Ach prévisionnel'!F8-'Ach prévisionnel'!K8)+'Ach prévisionnel'!I22+'Ach prévisionnel'!I35 -> 116897.53 | D21: =+(B21/0.9)*0.025 -> 4226.25 | E21: =+'Cout de production prévisionnel'!E8-'Cout de production prévisionnel'!I8 -> -526.46461 | F21: =+(B21-(C21+D21+E21)) -> 31547.687 | G21: =+F21/B21 -> 0.20735277
A22: PF Amande | B22: =+'Chiffre d''affaire'!L9 -> 152145 | C22: =('Ach prévisionnel'!I9+'Ach prévisionnel'!F9-'Ach prévisionnel'!K9)+'Ach prévisionnel'!I23+'Ach prévisionnel'!I36 -> 131594 | D22: =+(B22/0.9)*0.025 -> 4226.25 | E22: =+'Cout de production prévisionnel'!E9-'Cout de production prévisionnel'!I9 -> -588.04203 | F22: =+(B22-(C22+D22+E22)) -> 16912.787 | G22: =+F22/B22 -> 0.11116229
B24: =SUM(B16:B23) -> 2003594.4 | C24: =SUM(C16:C23) -> 1256800.1 | D24: =SUM(D16:D23) -> 55655.4 | E24: =SUM(E16:E23) -> -6080.7751 | F24: =SUM(F16:F23) -> 697219.64 | G24: =+F24/B24 -> 0.34798442 | I24: =SUM(C24:E24) -> 1306374.8
A25: 2018
A26: Produits | B26: Chiffre d'affaire | C26: Consommations matière | D26: Consommations Autres approv | E26: Variation St. P finis | F26: Marge Brut | G26: Taux de marge
A27: PF Mais | B27: =+'Chiffre d''affaire'!N3 -> 445629.6 | C27: =+('Ach prévisionnel'!N3+'Ach prévisionnel'!K3-'Ach prévisionnel'!P3)+'Ach prévisionnel'!N17+'Ach prévisionnel'!N30 -> 234143.37 | D27: =+(B27/0.9)*0.025 -> 12378.6 | E27: ='Cout de production prévisionnel'!I3-'Cout de production prévisionnel'!M3 -> -1226.763 | F27: =+(B27-(C27+D27+E27)) -> 200334.4 | G27: =+F27/B27 -> 0.44955361
A28: PF Cacahuète | B28: =+'Chiffre d''affaire'!N4 -> 623881.44 | C28: =+('Ach prévisionnel'!N4+'Ach prévisionnel'!K4-'Ach prévisionnel'!P4)+'Ach prévisionnel'!N18+'Ach prévisionnel'!N31 -> 349649.28 | D28: =+(B28/0.9)*0.025 -> 17330.04 | E28: ='Cout de production prévisionnel'!I4-'Cout de production prévisionnel'!M4 -> -1731.5599 | F28: =+(B28-(C28+D28+E28)) -> 258633.68 | G28: =+F28/B28 -> 0.41455581
A29: PF Pois chiche | B29: =+'Chiffre d''affaire'!N5 -> 534755.52 | C29: =+('Ach prévisionnel'!N5+'Ach prévisionnel'!K5-'Ach prévisionnel'!P5)+'Ach prévisionnel'!N19+'Ach prévisionnel'!N32 -> 284363.33 | D29: =+(B29/0.9)*0.025 -> 14854.32 | E29: ='Cout de production prévisionnel'!I5-'Cout de production prévisionnel'!M5 -> -1447.5986 | F29: =+(B29-(C29+D29+E29)) -> 236985.47 | G29: =+F29/B29 -> 0.44316601
A30: PF noisette | B30: =+'Chiffre d''affaire'!N6 -> 174966.75 | C30: =+('Ach prévisionnel'!N6+'Ach prévisionnel'!K6-'Ach prévisionnel'!P6)+'Ach prévisionnel'!N20+'Ach prévisionnel'!N33 -> 145699.46 | D30: =+(B30/0.9)*0.025 -> 4860.1875 | E30: ='Cout de production prévisionnel'!I6-'Cout de production prévisionnel'!M6 -> -652.64366 | F30: =+(B30-(C30+D30+E30)) -> 25059.75 | G30: =+F30/B30 -> 0.14322579
A31: PF pistche | B31: =+'Chiffre d''affaire'!N7 -> 174966.75 | C31: =+('Ach prévisionnel'!N7+'Ach prévisionnel'!K7-'Ach prévisionnel'!P7)+'Ach prévisionnel'!N21+'Ach prévisionnel'!N34 -> 145699.46 | D31: =+(B31/0.9)*0.025 -> 4860.1875 | E31: ='Cout de production prévisionnel'!I7-'Cout de production prévisionnel'!M7 -> -652.64366 | F31: =+(B31-(C31+D31+E31)) -> 25059.75 | G31: =+F31/B31 -> 0.14322579
A32: PF acajou | B32: =+'Chiffre d''affaire'!N8 -> 174966.75 | C32: =+('Ach prévisionnel'!N8+'Ach prévisionnel'!K8-'Ach prévisionnel'!P8)+'Ach prévisionnel'!N22+'Ach prévisionnel'!N35 -> 134432.16 | D32: =+(B32/0.9)*0.025 -> 4860.1875 | E32: ='Cout de production prévisionnel'!I8-'Cout de production prévisionnel'!M8 -> -605.4343 | F32: =+(B32-(C32+D32+E32)) -> 36279.84 | G32: =+F32/B32 -> 0.20735277
A33: PF Amande | B33: =+'Chiffre d''affaire'!N9 -> 174966.75 | C33: =+('Ach prévisionnel'!N9+'Ach prévisionnel'!K9-'Ach prévisionnel'!P9)+'Ach prévisionnel'!N23+'Ach prévisionnel'!N36 -> 151333.11 | D33: =+(B33/0.9)*0.025 -> 4860.1875 | E33: ='Cout de production prévisionnel'!I9-'Cout de production prévisionnel'!M9 -> -676.24834 | F33: =+(B33-(C33+D33+E33)) -> 19449.705 | G33: =+F33/B33 -> 0.11116229
B35: =SUM(B27:B34) -> 2304133.6 | C35: =SUM(C27:C34) -> 1445320.2 | D35: =SUM(D27:D34) -> 64003.71 | E35: =SUM(E27:E34) -> -6992.8914 | F35: =SUM(F27:F34) -> 801802.59 | G35: =+F35/B35 -> 0.34798442 | I35: =SUM(C35:E35) -> 1502331
A36: 2019
A37: Produits | B37: Chiffre d'affaire | C37: Consommations matière | D37: Consommations Autres approv | E37: Variation St. P finis | F37: Marge Brut | G37: Taux de marge
A38: PF Mais | B38: =+'Chiffre d''affaire'!P3 -> 512474.04 | C38: =+('Ach prévisionnel'!S3+'Ach prévisionnel'!P3-'Ach prévisionnel'!U3)+'Ach prévisionnel'!S17+'Ach prévisionnel'!S30 -> 269264.87 | D38: =+(B38/0.9)*0.025 -> 14235.39 | E38: =+'Cout de production prévisionnel'!M3-'Cout de production prévisionnel'!Q3 -> -1410.7774 | F38: =+(B38-(C38+D38+E38)) -> 230384.56 | G38: =+F38/B38 -> 0.44955361
A39: PF Cacahuète | B39: =+'Chiffre d''affaire'!P4 -> 717463.66 | C39: =+('Ach prévisionnel'!S4+'Ach prévisionnel'!P4-'Ach prévisionnel'!U4)+'Ach prévisionnel'!S18+'Ach prévisionnel'!S31 -> 402096.67 | D39: =+(B39/0.9)*0.025 -> 19929.546 | E39: =+'Cout de production prévisionnel'!M4-'Cout de production prévisionnel'!Q4 -> -1991.2938 | F39: =+(B39-(C39+D39+E39)) -> 297428.73 | G39: =+F39/B39 -> 0.41455581
A40: PF Pois chiche | B40: =+'Chiffre d''affaire'!P5 -> 614968.85 | C40: =+('Ach prévisionnel'!S5+'Ach prévisionnel'!P5-'Ach prévisionnel'!U5)+'Ach prévisionnel'!S19+'Ach prévisionnel'!S32 -> 327017.83 | D40: =+(B40/0.9)*0.025 -> 17082.468 | E40: =+'Cout de production prévisionnel'!M5-'Cout de production prévisionnel'!Q5 -> -1664.7384 | F40: =+(B40-(C40+D40+E40)) -> 272533.29 | G40: =+F40/B40 -> 0.44316601
A41: PF noisette | B41: =+'Chiffre d''affaire'!P6 -> 201211.76 | C41: =+('Ach prévisionnel'!S6+'Ach prévisionnel'!P6-'Ach prévisionnel'!U6)+'Ach prévisionnel'!S20+'Ach prévisionnel'!S33 -> 167554.37 | D41: =+(B41/0.9)*0.025 -> 5589.2156 | E41: =+'Cout de production prévisionnel'!M6-'Cout de production prévisionnel'!Q6 -> -750.54021 | F41: =+(B41-(C41+D41+E41)) -> 28818.713 | G41: =+F41/B41 -> 0.14322579
A42: PF pistche | B42: =+'Chiffre d''affaire'!P7 -> 201211.76 | C42: =+('Ach prévisionnel'!S7+'Ach prévisionnel'!P7-'Ach prévisionnel'!U7)+'Ach prévisionnel'!S21+'Ach prévisionnel'!S34 -> 167554.37 | D42: =+(B42/0.9)*0.025 -> 5589.2156 | E42: =+'Cout de production prévisionnel'!M7-'Cout de production prévisionnel'!Q7 -> -750.54021 | F42: =+(B42-(C42+D42+E42)) -> 28818.713 | G42: =+F42/B42 -> 0.14322579
A43: PF acajou | B43: =+'Chiffre d''affaire'!P8 -> 201211.76 | C43: =+('Ach prévisionnel'!S8+'Ach prévisionnel'!P8-'Ach prévisionnel'!U8)+'Ach prévisionnel'!S22+'Ach prévisionnel'!S35 -> 154596.98 | D43: =+(B43/0.9)*0.025 -> 5589.2156 | E43: =+'Cout de production prévisionnel'!M8-'Cout de production prévisionnel'!Q8 -> -696.24945 | F43: =+(B43-(C43+D43+E43)) -> 41721.816 | G43: =+F43/B43 -> 0.20735277
A44: PF Amande | B44: =+'Chiffre d''affaire'!P9 -> 201211.76 | C44: =+('Ach prévisionnel'!S9+'Ach prévisionnel'!P9-'Ach prévisionnel'!U9)+'Ach prévisionnel'!S23+'Ach prévisionnel'!S36 -> 174033.07 | D44: =+(B44/0.9)*0.025 -> 5589.2156 | E44: =+'Cout de production prévisionnel'!M9-'Cout de production prévisionnel'!Q9 -> -777.68559 | F44: =+(B44-(C44+D44+E44)) -> 22367.161 | G44: =+F44/B44 -> 0.11116229
B46: =SUM(B38:B45) -> 2649753.6 | C46: =SUM(C38:C45) -> 1662118.2 | D46: =SUM(D38:D45) -> 73604.266 | E46: =SUM(E38:E45) -> -8041.8251 | F46: =SUM(F38:F45) -> 922072.98 | G46: =+F46/B46 -> 0.34798442 | I46: =SUM(C46:E46) -> 1727680.6
...

Sheet Consommations Q
A2: Matière premières | B2: 2016 | G2: 2017 | L2: 2018 | Q2: 2019 | V2: 2020 | AA2: 2021 | AF2: 2022
B3: Qt Vendu | C3: Qt produite | D3: Qt Consommées | E3: Qt achétées | F3: Qt SF | G3: Qt Vendu | H3: Qt produite | I3: Qt Consommées | J3: Qt achétée | K3: Qt SF | L3: Qt Vendu | M3: Qt produite | N3: Qt Consommées | O3: Qt achétée | P3: Qt SF | Q3: Qt Vendu | R3: Qt produite | S3: Qt Consommées | T3: Qt achétée | U3: Qt SF | V3: Qt Vendu | W3: Qt produite | X3: Qt Consommées | Y3: Qt achétée | Z3: Qt SF | AA3: Qt Vendu | AB3: Qt produite | AC3: Qt Consommées | AD3: Qt achétée | AE3: Qt SF | AF3: Qt Vendu | AG3: Qt produite | AH3: Qt Consommées | AI3: Qt achétée | AJ3: Qt SF
A4: MP MAIS | B4: =+'Chiffre d''affaire'!F3 -> 37440 | C4: =+B4+'Cout de production prévisionnel'!D3 -> 38647.742 | D4: =+C4*1.01 -> 39034.219 | E4: =+D4*13/12 -> 42287.071 | F4: =+E4/13 -> 3252.8516 | G4: =+B4*1.15 -> 43056 | H4: =+G4+'Cout de production prévisionnel'!H3-'Cout de production prévisionnel'!D3 -> 43237.161 | I4: =+H4*1.01 -> 43669.533 | J4: =+(I4-F4)*13/12 -> 43784.738 | K4: =+J4/13 -> 3368.0568 | L4: =+G4*1.15 -> 49514.4 | M4: =+L4+'Cout de production prévisionnel'!L3-'Cout de production prévisionnel'!H3 -> 49722.735 | N4: =+M4*1.01 -> 50219.963 | O4: =+(N4-K4)*13/12 -> 50756.232 | P4: =+O4/13 -> 3904.3255 | Q4: =+L4*1.15 -> 56941.56 | R4: =+Q4+'Cout de production prévisionnel'!P3-'Cout de production prévisionnel'!L3 -> 57181.146 | S4: =+R4*1.01 -> 57752.957 | T4: =+(S4-P4)*13/12 -> 58336.018 | U4: =+T4/13 -> 4487.386 | V4: =+Q4*1.15 -> 65482.794 | W4: =+V4+'Cout de production prévisionnel'!T3-'Cout de production prévisionnel'!P3 -> 65758.318 | X4: =+W4*1.01 -> 66415.901 | Y4: =+(X4-U4)*13/12 -> 67089.224 | Z4: =+Y4/13 -> 5160.7096 | AA4: =+V4 -> 65482.794 | AB4: =+AA4+'Cout de production prévisionnel'!X3-'Cout de production prévisionnel'!T3 -> 65482.794 | AC4: =+AB4*1.01 -> 66137.622 | AD4: =+(AC4-Z4)*13/12 -> 66058.322 | AE4: =+AD4/13 -> 5081.4094 | AF4: =+AA4 -> 65482.794 | AG4: =+AF4+'Cout de production prévisionnel'!AB3-'Cout de production prévisionnel'!X3 -> 65482.794 | AH4: =+AG4*1.01 -> 66137.622 | AI4: =+(AH4-AE4)*13/12 -> 66144.23 | AJ4: =+AI4/13 -> 5088.0177
A5: MP Cacahuète | B5: =+'Chiffre d''affaire'!F4 -> 37440 | C5: =+B5+'Cout de production prévisionnel'!D4 -> 38647.742 | D5: =+C5*1.01 -> 39034.219 | E5: =+D5*13/12 -> 42287.071 | F5: =+E5/13 -> 3252.8516 | G5: =+B5*1.15 -> 43056 | H5: =+G5+'Cout de production prévisionnel'!H4-'Cout de production prévisionnel'!D4 -> 43237.161 | I5: =+H5*1.01 -> 43669.533 | J5: =+(I5-F5)*13/12 -> 43784.738 | K5: =+J5/13 -> 3368.0568 | L5: =+G5*1.15 -> 49514.4 | M5: =+L5+'Cout de production prévisionnel'!L4-'Cout de production prévisionnel'!H4 -> 49722.735 | N5: =+M5*1.01 -> 50219.963 | O5: =+(N5-K5)*13/12 -> 50756.232 | P5: =+O5/13 -> 3904.3255 | Q5: =+L5*1.15 -> 56941.56 | R5: =+Q5+'Cout de production prévisionnel'!P4-'Cout de production prévisionnel'!L4 -> 57181.146 | S5: =+R5*1.01 -> 57752.957 | T5: =+(S5-P5)*13/12 -> 58336.018 | U5: =+T5/13 -> 4487.386 | V5: =+Q5*1.15 -> 65482.794 | W5: =+V5+'Cout de production prévisionnel'!T4-'Cout de production prévisionnel'!P4 -> 65758.318 | X5: =+W5*1.01 -> 66415.901 | Y5: =+(X5-U5)*13/12 -> 67089.224 | Z5: =+Y5/13 -> 5160.7096 | AA5: =+V5 -> 65482.794 | AB5: =+AA5+'Cout de production prévisionnel'!X4-'Cout de production prévisionnel'!T4 -> 65482.794 | AC5: =+AB5*1.01 -> 66137.622 | AD5: =+(AC5-Z5)*13/12 -> 66058.322 | AE5: =+AD5/13 -> 5081.4094 | AF5: =+AA5 -> 65482.794 | AG5: =+AF5+'Cout de production prévisionnel'!AB4-'Cout de production prévisionnel'!X4 -> 65482.794 | AH5: =+AG5*1.01 -> 66137.622 | AI5: =+(AH5-AE5)*13/12 -> 66144.23 | AJ5: =+AI5/13 -> 5088.0177
A6: Pois chiche | B6: =+'Chiffre d''affaire'!F5 -> 37440 | C6: =+B6+'Cout de production prévisionnel'!D5 -> 38647.742 | D6: =+C6*1.01 -> 39034.219 | E6: =+D6*13/12 -> 42287.071 | F6: =+E6/13 -> 3252.8516 | G6: =+B6*1.15 -> 43056 | H6: =+G6+'Cout de production prévisionnel'!H5-'Cout de production prévisionnel'!D5 -> 43237.161 | I6: =+H6*1.01 -> 43669.533 | J6: =+(I6-F6)*13/12 -> 43784.738 | K6: =+J6/13 -> 3368.0568 | L6: =+G6*1.15 -> 49514.4 | M6: =+L6+'Cout de production prévisionnel'!L5-'Cout de production prévisionnel'!H5 -> 49722.735 | N6: =+M6*1.01 -> 50219.963 | O6: =+(N6-K6)*13/12 -> 50756.232 | P6: =+O6/13 -> 3904.3255 | Q6: =+L6*1.15 -> 56941.56 | R6: =+Q6+'Cout de production prévisionnel'!P5-'Cout de production prévisionnel'!L5 -> 57181.146 | S6: =+R6*1.01 -> 57752.957 | T6: =+(S6-P6)*13/12 -> 58336.018 | U6: =+T6/13 -> 4487.386 | V6: =+Q6*1.15 -> 65482.794 | W6: =+V6+'Cout de production prévisionnel'!T5-'Cout de production prévisionnel'!P5 -> 65758.318 | X6: =+W6*1.01 -> 66415.901 | Y6: =+(X6-U6)*13/12 -> 67089.224 | Z6: =+Y6/13 -> 5160.7096 | AA6: =+V6 -> 65482.794 | AB6: =+AA6+'Cout de production prévisionnel'!X5-'Cout de production prévisionnel'!T5 -> 65482.794 | AC6: =+AB6*1.01 -> 66137.622 | AD6: =+(AC6-Z6)*13/12 -> 66058.322 | AE6: =+AD6/13 -> 5081.4094 | AF6: =+AA6 -> 65482.794 | AG6: =+AF6+'Cout de production prévisionnel'!AB5-'Cout de production prévisionnel'!X5 -> 65482.794 | AH6: =+AG6*1.01 -> 66137.622 | AI6: =+(AH6-AE6)*13/12 -> 66144.23 | AJ6: =+AI6/13 -> 5088.0177
A7: MP noisette | B7: =+'Chiffre d''affaire'!F6 -> 4200 | C7: =+B7+'Cout de production prévisionnel'!D6 -> 4335.4839 | D7: =+C7*1.01 -> 4378.8387 | E7: =+D7*13/12 -> 4743.7419 | F7: =+E7/13 -> 364.90323 | G7: =+B7*1.15 -> 4830 | H7: =+G7+'Cout de production prévisionnel'!H6-'Cout de production prévisionnel'!D6 -> 4850.3226 | I7: =+H7*1.01 -> 4898.8258 | J7: =+(I7-F7)*13/12 -> 4911.7495 | K7: =+J7/13 -> 377.82688 | L7: =+G7*1.15 -> 5554.5 | M7: =+L7+'Cout de production prévisionnel'!L6-'Cout de production prévisionnel'!H6 -> 5577.871 | N7: =+M7*1.01 -> 5633.6497 | O7: =+(N7-K7)*13/12 -> 5693.808 | P7: =+O7/13 -> 437.98523 | Q7: =+L7*1.15 -> 6387.675 | R7: =+Q7+'Cout de production prévisionnel'!P6-'Cout de production prévisionnel'!L6 -> 6414.5516 | S7: =+R7*1.01 -> 6478.6971 | T7: =+(S7-P7)*13/12 -> 6544.1046 | U7: =+T7/13 -> 503.39266 | V7: =+Q7*1.15 -> 7345.8262 | W7: =+V7+'Cout de production prévisionnel'!T6-'Cout de production prévisionnel'!P6 -> 7376.7344 | X7: =+W7*1.01 -> 7450.5017 | Y7: =+(X7-U7)*13/12 -> 7526.0348 | Z7: =+Y7/13 -> 578.92575 | AA7: =+V7 -> 7345.8262 | AB7: =+AA7+'Cout de production prévisionnel'!X6-'Cout de production prévisionnel'!T6 -> 7345.8262 | AC7: =+AB7*1.01 -> 7419.2845 | AD7: =+(AC7-Z7)*13/12 -> 7410.3887 | AE7: =+AD7/13 -> 570.0299 | AF7: =+AA7 -> 7345.8262 | AG7: =+AF7+'Cout de production prévisionnel'!AB6-'Cout de production prévisionnel'!X6 -> 7345.8262 | AH7: =+AG7*1.01 -> 7419.2845 | AI7: =+(AH7-AE7)*13/12 -> 7420.0258 | AJ7: =+AI7/13 -> 570.77122
A8: MP pistche | B8: =+'Chiffre d''affaire'!F7 -> 4200 | C8: =+B8+'Cout de production prévisionnel'!D7 -> 4335.4839 | D8: =+C8*1.01 -> 4378.8387 | E8: =+D8*13/12 -> 4743.7419 | F8: =+E8/13 -> 364.90323 | G8: =+B8*1.15 -> 4830 | H8: =+G8+'Cout de production prévisionnel'!H7-'Cout de production prévisionnel'!D7 -> 4850.3226 | I8: =+H8*1.01 -> 4898.8258 | J8: =+(I8-F8)*13/12 -> 4911.7495 | K8: =+J8/13 -> 377.82688 | L8: =+G8*1.15 -> 5554.5 | M8: =+L8+'Cout de production prévisionnel'!L7-'Cout de production prévisionnel'!H7 -> 5577.871 | N8: =+M8*1.01 -> 5633.6497 | O8: =+(N8-K8)*13/12 -> 5693.808 | P8: =+O8/13 -> 437.98523 | Q8: =+L8*1.15 -> 6387.675 | R8: =+Q8+'Cout de production prévisionnel'!P7-'Cout de production prévisionnel'!L7 -> 6414.5516 | S8: =+R8*1.01 -> 6478.6971 | T8: =+(S8-P8)*13/12 -> 6544.1046 | U8: =+T8/13 -> 503.39266 | V8: =+Q8*1.15 -> 7345.8262 | W8: =+V8+'Cout de production prévisionnel'!T7-'Cout de production prévisionnel'!P7 -> 7376.7344 | X8: =+W8*1.01 -> 7450.5017 | Y8: =+(X8-U8)*13/12 -> 7526.0348 | Z8: =+Y8/13 -> 578.92575 | AA8: =+V8 -> 7345.8262 | AB8: =+AA8+'Cout de production prévisionnel'!X7-'Cout de production prévisionnel'!T7 -> 7345.8262 | AC8: =+AB8*1.01 -> 7419.2845 | AD8: =+(AC8-Z8)*13/12 -> 7410.3887 | AE8: =+AD8/13 -> 570.0299 | AF8: =+AA8 -> 7345.8262 | AG8: =+AF8+'Cout de production prévisionnel'!AB7-'Cout de production prévisionnel'!X7 -> 7345.8262 | AH8: =+AG8*1.01 -> 7419.2845 | AI8: =+(AH8-AE8)*13/12 -> 7420.0258 | AJ8: =+AI8/13 -> 570.77122
A9: MP acajou | B9: =+'Chiffre d''affaire'!F8 -> 4200 | C9: =+B9+'Cout de production prévisionnel'!D8 -> 4335.4839 | D9: =+C9*1.01 -> 4378.8387 | E9: =+D9*13/12 -> 4743.7419 | F9: =+E9/13 -> 364.90323 | G9: =+B9*1.15 -> 4830 | H9: =+G9+'Cout de production prévisionnel'!H8-'Cout de production prévisionnel'!D8 -> 4850.3226 | I9: =+H9*1.01 -> 4898.8258 | J9: =+(I9-F9)*13/12 -> 4911.7495 | K9: =+J9/13 -> 377.82688 | L9: =+G9*1.15 -> 5554.5 | M9: =+L9+'Cout de production prévisionnel'!L8-'Cout de production prévisionnel'!H8 -> 5577.871 | N9: =+M9*1.01 -> 5633.6497 | O9: =+(N9-K9)*13/12 -> 5693.808 | P9: =+O9/13 -> 437.98523 | Q9: =+L9*1.15 -> 6387.675 | R9: =+Q9+'Cout de production prévisionnel'!P8-'Cout de production prévisionnel'!L8 -> 6414.5516 | S9: =+R9*1.01 -> 6478.6971 | T9: =+(S9-P9)*13/12 -> 6544.1046 | U9: =+T9/13 -> 503.39266 | V9: =+Q9*1.15 -> 7345.8262 | W9: =+V9+'Cout de production prévisionnel'!T8-'Cout de production prévisionnel'!P8 -> 7376.7344 | X9: =+W9*1.01 -> 7450.5017 | Y9: =+(X9-U9)*13/12 -> 7526.0348 | Z9: =+Y9/13 -> 578.92575 | AA9: =+V9 -> 7345.8262 | AB9: =+AA9+'Cout de production prévisionnel'!X8-'Cout de production prévisionnel'!T8 -> 7345.8262 | AC9: =+AB9*1.01 -> 7419.2845 | AD9: =+(AC9-Z9)*13/12 -> 7410.3887 | AE9: =+AD9/13 -> 570.0299 | AF9: =+AA9 -> 7345.8262 | AG9: =+AF9+'Cout de production prévisionnel'!AB8-'Cout de production prévisionnel'!X8 -> 7345.8262 | AH9: =+AG9*1.01 -> 7419.2845 | AI9: =+(AH9-AE9)*13/12 -> 7420.0258 | AJ9: =+AI9/13 -> 570.77122
A10: MP Amande | B10: =+'Chiffre d''affaire'!F9 -> 4200 | C10: =+B10+'Cout de production prévisionnel'!D9 -> 4335.4839 | D10: =+C10*1.01 -> 4378.8387 | E10: =+D10*13/12 -> 4743.7419 | F10: =+E10/13 -> 364.90323 | G10: =+B10*1.15 -> 4830 | H10: =+G10+'Cout de production prévisionnel'!H9-'Cout de production prévisionnel'!D9 -> 4850.3226 | I10: =+H10*1.01 -> 4898.8258 | J10: =+(I10-F10)*13/12 -> 4911.7495 | K10: =+J10/13 -> 377.82688 | L10: =+G10*1.15 -> 5554.5 | M10: =+L10+'Cout de production prévisionnel'!L9-'Cout de production prévisionnel'!H9 -> 5577.871 | N10: =+M10*1.01 -> 5633.6497 | O10: =+(N10-K10)*13/12 -> 5693.808 | P10: =+O10/13 -> 437.98523 | Q10: =+L10*1.15 -> 6387.675 | R10: =+Q10+'Cout de production prévisionnel'!P9-'Cout de production prévisionnel'!L9 -> 6414.5516 | S10: =+R10*1.01 -> 6478.6971 | T10: =+(S10-P10)*13/12 -> 6544.1046 | U10: =+T10/13 -> 503.39266 | V10: =+Q10*1.15 -> 7345.8262 | W10: =+V10+'Cout de production prévisionnel'!T9-'Cout de production prévisionnel'!P9 -> 7376.7344 | X10: =+W10*1.01 -> 7450.5017 | Y10: =+(X10-U10)*13/12 -> 7526.0348 | Z10: =+Y10/13 -> 578.92575 | AA10: =+V10 -> 7345.8262 | AB10: =+AA10+'Cout de production prévisionnel'!X9-'Cout de production prévisionnel'!T9 -> 7345.8262 | AC10: =+AB10*1.01 -> 7419.2845 | AD10: =+(AC10-Z10)*13/12 -> 7410.3887 | AE10: =+AD10/13 -> 570.0299 | AF10: =+AA10 -> 7345.8262 | AG10: =+AF10+'Cout de production prévisionnel'!AB9-'Cout de production prévisionnel'!X9 -> 7345.8262 | AH10: =+AG10*1.01 -> 7419.2845 | AI10: =+(AH10-AE10)*13/12 -> 7420.0258 | AJ10: =+AI10/13 -> 570.77122
B11: =SUM(B4:B10) -> 129120 | C11: =SUM(C4:C10) -> 133285.16 | D11: =SUM(D4:D10) -> 134618.01 | E11: =SUM(E4:E10) -> 145836.18 | F11: =SUM(F4:F10) -> 11218.168 | G11: =SUM(G4:G10) -> 148488 | H11: =SUM(H4:H10) -> 149112.77 | I11: =SUM(I4:I10) -> 150603.9 | ... AJ11: =SUM(AJ4:AJ10) -> 17547.138
G12: =+H11+'Cout de production prévisionnel'!D10-'Cout de production prévisionnel'!H10 -> 148488
A13: Check St. F | F13: =+E11-D11-F11 -> 1.6370905e-11 | K13: =+J11-I11+F11-K11 -> -5.0931703e-11 | P13: =+O11-N11+K11-P11 -> -3.2741809e-11 | U13: =+T11-S11+P11-U11 -> 0 | Z13: =+Y11-X11+U11-Z11 -> 0 | AE13: =+AD11-AC11+Z11-AE11 -> 0 | AJ13: =+AI11-AH11+AE11-AJ11 -> 9.8225428e-11
